2024-02-21 13:26:47,482 : INFO : Start of Training
2024-02-21 13:26:47,482 : INFO : Run_id:2024-02-21_132647_506983753
2024-02-21 13:26:47,482 : INFO : Start of Data Load, validation and transformation
2024-02-21 13:26:47,483 : INFO : Start of Archiving Old Rejected Files...
2024-02-21 13:26:47,483 : INFO : End of Archiving Old Rejected Files...
2024-02-21 13:26:47,483 : INFO : Start of Archiving Old Validated Files...
2024-02-21 13:26:47,484 : INFO : End of Archiving Old Validated Files...
2024-02-21 13:26:47,484 : INFO : Start of Archiving Old Processed Files...
2024-02-21 13:26:47,485 : INFO : End of Archiving Old Processed Files...
2024-02-21 13:26:47,486 : INFO : Start of Archiving Old Result Files...
2024-02-21 13:26:47,486 : INFO : End of Archiving Old Result Files...
2024-02-21 13:26:47,486 : INFO : Start of Reading values From Schema...
2024-02-21 13:26:47,487 : INFO : End of Reading values From Schema...
2024-02-21 13:26:47,487 : INFO : Start of Validating Column Length...
2024-02-21 13:26:47,492 : INFO : Invalid Columns Length :: diabetes.csv
2024-02-21 13:26:47,507 : INFO : End of Validating Column Length...
2024-02-21 13:26:47,507 : INFO : Start of Validating Missing Values...
2024-02-21 13:26:47,523 : INFO : End of Validating Missing Values...
2024-02-21 13:26:47,524 : INFO : Start of Replacing Missing Values with NULL...
2024-02-21 13:26:47,577 : INFO : hr_employee_churn_data.csv: File Transformed successfully!!
2024-02-21 13:26:47,578 : INFO : End of Replacing Missing Values with NULL...
2024-02-21 13:26:47,578 : INFO : Start of Creating Table...
2024-02-21 13:26:47,578 : INFO : Opened training database successfully
2024-02-21 13:26:47,578 : INFO : Tables created successfully
2024-02-21 13:26:47,578 : INFO : Closed training database successfully
2024-02-21 13:26:47,578 : INFO : End of Creating Table...
2024-02-21 13:26:47,578 : INFO : Opened training database successfully
2024-02-21 13:26:47,580 : INFO : Start of Inserting Data into Table...
2024-02-21 13:26:47,580 : ERROR : Exception raised while Inserting Data into Table: table training_raw_data_t has 9 columns but 10 values were supplied 
Traceback (most recent call last):
  File "C:\Users\MCS\PycharmProjects\MCSProject\pythonProject\apps\database\database_operation.py", line 92, in insert_data
    conn.execute("INSERT INTO "+table_name+" values ({values})".format(values=(to_db)))
sqlite3.OperationalError: table training_raw_data_t has 9 columns but 10 values were supplied
2024-02-21 13:26:47,582 : INFO : End of Inserting Data into Table...
2024-02-21 13:26:47,582 : INFO : Start of Exporting Data into CSV...
2024-02-21 13:26:47,582 : INFO : Opened training database successfully
2024-02-21 13:26:47,587 : INFO : End of Exporting Data into CSV...
2024-02-21 13:26:47,587 : INFO : Start of Moving Processed Files...
2024-02-21 13:26:47,588 : INFO : End of Moving Processed Files...
2024-02-21 13:26:47,588 : INFO : End of Data Load, validation and transformation
2024-02-21 13:26:47,588 : INFO : Start of Preprocessing...
2024-02-21 13:26:47,588 : INFO : Start of reading dataset...
2024-02-21 13:26:47,590 : INFO : End of reading dataset...
2024-02-21 13:26:47,590 : INFO : Start of Droping Columns...
2024-02-21 13:26:47,590 : ERROR : Exception raised while Droping Columns:"['empid'] not found in axis"
Traceback (most recent call last):
  File "C:\Users\MCS\PycharmProjects\MCSProject\pythonProject\apps\preprocess\preprocessor.py", line 49, in drop_columns
    self.useful_data=self.data.drop(labels=self.columns, axis=1) # drop the labels specified in the columns
                     ^^^^^^^^^^^^^^^^^^^^^^^^^^^^^^^^^^^^^^^^^^^
  File "C:\Users\MCS\PycharmProjects\MCSProject\pythonProject\venv\Lib\site-packages\pandas\core\frame.py", line 5568, in drop
    return super().drop(
           ^^^^^^^^^^^^^
  File "C:\Users\MCS\PycharmProjects\MCSProject\pythonProject\venv\Lib\site-packages\pandas\core\generic.py", line 4782, in drop
    obj = obj._drop_axis(labels, axis, level=level, errors=errors)
          ^^^^^^^^^^^^^^^^^^^^^^^^^^^^^^^^^^^^^^^^^^^^^^^^^^^^^^^^
  File "C:\Users\MCS\PycharmProjects\MCSProject\pythonProject\venv\Lib\site-packages\pandas\core\generic.py", line 4824, in _drop_axis
    new_axis = axis.drop(labels, errors=errors)
               ^^^^^^^^^^^^^^^^^^^^^^^^^^^^^^^^
  File "C:\Users\MCS\PycharmProjects\MCSProject\pythonProject\venv\Lib\site-packages\pandas\core\indexes\base.py", line 7069, in drop
    raise KeyError(f"{labels[mask].tolist()} not found in axis")
KeyError: "['empid'] not found in axis"
2024-02-21 13:26:47,596 : ERROR : Unsuccessful End of Preprocessing...
Traceback (most recent call last):
  File "C:\Users\MCS\PycharmProjects\MCSProject\pythonProject\apps\preprocess\preprocessor.py", line 49, in drop_columns
    self.useful_data=self.data.drop(labels=self.columns, axis=1) # drop the labels specified in the columns
                     ^^^^^^^^^^^^^^^^^^^^^^^^^^^^^^^^^^^^^^^^^^^
  File "C:\Users\MCS\PycharmProjects\MCSProject\pythonProject\venv\Lib\site-packages\pandas\core\frame.py", line 5568, in drop
    return super().drop(
           ^^^^^^^^^^^^^
  File "C:\Users\MCS\PycharmProjects\MCSProject\pythonProject\venv\Lib\site-packages\pandas\core\generic.py", line 4782, in drop
    obj = obj._drop_axis(labels, axis, level=level, errors=errors)
          ^^^^^^^^^^^^^^^^^^^^^^^^^^^^^^^^^^^^^^^^^^^^^^^^^^^^^^^^
  File "C:\Users\MCS\PycharmProjects\MCSProject\pythonProject\venv\Lib\site-packages\pandas\core\generic.py", line 4824, in _drop_axis
    new_axis = axis.drop(labels, errors=errors)
               ^^^^^^^^^^^^^^^^^^^^^^^^^^^^^^^^
  File "C:\Users\MCS\PycharmProjects\MCSProject\pythonProject\venv\Lib\site-packages\pandas\core\indexes\base.py", line 7069, in drop
    raise KeyError(f"{labels[mask].tolist()} not found in axis")
KeyError: "['empid'] not found in axis"

During handling of the above exception, another exception occurred:

Traceback (most recent call last):
  File "C:\Users\MCS\PycharmProjects\MCSProject\pythonProject\apps\preprocess\preprocessor.py", line 186, in preprocess_trainset
    data=self.drop_columns(data,['empid'])
         ^^^^^^^^^^^^^^^^^^^^^^^^^^^^^^^^^
  File "C:\Users\MCS\PycharmProjects\MCSProject\pythonProject\apps\preprocess\preprocessor.py", line 54, in drop_columns
    raise Exception()
Exception
2024-02-21 13:26:47,597 : ERROR : Unsuccessful End of Training
Traceback (most recent call last):
  File "C:\Users\MCS\PycharmProjects\MCSProject\pythonProject\apps\preprocess\preprocessor.py", line 49, in drop_columns
    self.useful_data=self.data.drop(labels=self.columns, axis=1) # drop the labels specified in the columns
                     ^^^^^^^^^^^^^^^^^^^^^^^^^^^^^^^^^^^^^^^^^^^
  File "C:\Users\MCS\PycharmProjects\MCSProject\pythonProject\venv\Lib\site-packages\pandas\core\frame.py", line 5568, in drop
    return super().drop(
           ^^^^^^^^^^^^^
  File "C:\Users\MCS\PycharmProjects\MCSProject\pythonProject\venv\Lib\site-packages\pandas\core\generic.py", line 4782, in drop
    obj = obj._drop_axis(labels, axis, level=level, errors=errors)
          ^^^^^^^^^^^^^^^^^^^^^^^^^^^^^^^^^^^^^^^^^^^^^^^^^^^^^^^^
  File "C:\Users\MCS\PycharmProjects\MCSProject\pythonProject\venv\Lib\site-packages\pandas\core\generic.py", line 4824, in _drop_axis
    new_axis = axis.drop(labels, errors=errors)
               ^^^^^^^^^^^^^^^^^^^^^^^^^^^^^^^^
  File "C:\Users\MCS\PycharmProjects\MCSProject\pythonProject\venv\Lib\site-packages\pandas\core\indexes\base.py", line 7069, in drop
    raise KeyError(f"{labels[mask].tolist()} not found in axis")
KeyError: "['empid'] not found in axis"

During handling of the above exception, another exception occurred:

Traceback (most recent call last):
  File "C:\Users\MCS\PycharmProjects\MCSProject\pythonProject\apps\preprocess\preprocessor.py", line 186, in preprocess_trainset
    data=self.drop_columns(data,['empid'])
         ^^^^^^^^^^^^^^^^^^^^^^^^^^^^^^^^^
  File "C:\Users\MCS\PycharmProjects\MCSProject\pythonProject\apps\preprocess\preprocessor.py", line 54, in drop_columns
    raise Exception()
Exception

During handling of the above exception, another exception occurred:

Traceback (most recent call last):
  File "C:\Users\MCS\PycharmProjects\MCSProject\pythonProject\apps\training\train_model.py", line 35, in training_model
    self.X, self.y = self.preProcess.preprocess_trainset()
                     ^^^^^^^^^^^^^^^^^^^^^^^^^^^^^^^^^^^^^
  File "C:\Users\MCS\PycharmProjects\MCSProject\pythonProject\apps\preprocess\preprocessor.py", line 203, in preprocess_trainset
    raise Exception
Exception
